Workbook

Sheet Tổng hợp hồ sơ
A1: TỔNG HỢP HỒ SƠ QUẢN LÝ DỰ ÁN
A2: Hệ Thống Cảnh Báo Sớm Học Sinh Có Nguy Cơ Sư Phạm (VSF Student Risk Alert - VSF SRA)
A4: Tình hình hiện tại | B4: Đang triển khai (đúng tiến độ)
A5: Tên dự án | B5: VSF STUDENT RISK ALERT
A6: Ngày bắt đầu | B6: 46219
A7: Ngày kết thúc dự kiến | B7: 46262
A8: Trưởng nhóm | B8: Nguyễn Lê Thanh Điệp
A9: Mentor phụ trách | B9: Huỳnh Việt Linh (v.linhhv12@vinsmartfuture.tech) Nguyễn Thành Đăng (v.dangnt11@vinsmartfuture.tech))
A10: Đối tác sử dụng (Stakeholder) | B10: Vinschool
A11: Kho lưu mã nguồn (GitHub) | B11: Chưa có
A12: Địa chỉ sản phẩm (Live URL) | B12: Chưa có
A13: Mục tiêu dự án | B13: Xây dựng hệ thống cảnh báo sớm học sinh có nguy cơ học thuật/hành vi dựa trên dữ liệu School Online Schema. Hệ thống tích hợp 4 module chính: Text-to-Query (hỏi đáp dữ liệu), Multi-Agent (phân tích chỉ số chuyên sâu), RAG+LLM (đánh giá đề thi) và OCR (nhập điểm tự động).
A15: TỔNG HỢP TIẾN ĐỘ THEO SPRINT (Water-Scrum-Fall)
A16: Sprint | B16: Giai đoạn | C16: Tổng số việc | D16: Đã xong | E16: Đang làm | F16: Trạng thái
A17: Sprint 1 | B17: Tuần 0: Khởi động, thống nhất phạm vi, mini-SRS & thiết kế kiến trúc | C17: =COUNTA(Backlog!A4:A6) -> 3 | D17: =COUNTIF(Backlog!G4:G6,"Hoàn thành") -> 1 | E17: =COUNTIF(Backlog!G4:G6,"Đang làm") -> 2 | F17: =IF(C17=D17,"Hoàn thành",IF(AND(D17=0,E17=0),"Chưa bắt đầu","Đang làm")) -> Đang làm
A18: Sprint 2 | B18: Tuần 1: Thiết lập môi trường & ERD dữ liệu giả | C18: =COUNTA(Backlog!A8:A11) -> 4 | D18: =COUNTIF(Backlog!G8:G11,"Hoàn thành") -> 0 | E18: =COUNTIF(Backlog!G8:G11,"Đang làm") -> 0 | F18: =IF(C18=D18,"Hoàn thành",IF(AND(D18=0,E18=0),"Chưa bắt đầu","Đang làm")) -> Chưa bắt đầu
A19: Sprint 3 | B19: Tuần 2: Module Text-to-Query (NL-to-Query) | C19: =COUNTA(Backlog!A13:A15) -> 3 | D19: =COUNTIF(Backlog!G13:G15,"Hoàn thành") -> 0 | E19: =COUNTIF(Backlog!G13:G15,"Đang làm") -> 0 | F19: =IF(C19=D19,"Hoàn thành",IF(AND(D19=0,E19=0),"Chưa bắt đầu","Đang làm")) -> Chưa bắt đầu
A20: Sprint 4 | B20: Tuần 3: Phân tích các yếu tố tác động | C20: =COUNTA(Backlog!A17:A19) -> 3 | D20: =COUNTIF(Backlog!G17:G19,"Hoàn thành") -> 0 | E20: =COUNTIF(Backlog!G17:G19,"Đang làm") -> 0 | F20: =IF(C20=D20,"Hoàn thành",IF(AND(D20=0,E20=0),"Chưa bắt đầu","Đang làm")) -> Chưa bắt đầu
A21: Sprint 5 | B21: Tuần 4: Module Multi-Agent & Dự báo học lực | C21: =COUNTA(Backlog!A21:A23) -> 3 | D21: =COUNTIF(Backlog!G21:G23,"Hoàn thành") -> 0 | E21: =COUNTIF(Backlog!G21:G23,"Đang làm") -> 0 | F21: =IF(C21=D21,"Hoàn thành",IF(AND(D21=0,E21=0),"Chưa bắt đầu","Đang làm")) -> Chưa bắt đầu
A22: Sprint 6 | B22: Tuần 5: Module RAG + LLM & OCR | C22: =COUNTA(Backlog!A25:A27) -> 3 | D22: =COUNTIF(Backlog!G25:G27,"Hoàn thành") -> 0 | E22: =COUNTIF(Backlog!G25:G27,"Đang làm") -> 0 | F22: =IF(C22=D22,"Hoàn thành",IF(AND(D22=0,E22=0),"Chưa bắt đầu","Đang làm")) -> Chưa bắt đầu
A23: Sprint 7 | B23: Tuần 6: Kiểm thử toàn diện, UI Dashboard, Triển khai & Bàn giao | C23: =COUNTA(Backlog!A29:A31) -> 3 | D23: =COUNTIF(Backlog!G29:G31,"Hoàn thành") -> 0 | E23: =COUNTIF(Backlog!G29:G31,"Đang làm") -> 0 | F23: =IF(C23=D23,"Hoàn thành",IF(AND(D23=0,E23=0),"Chưa bắt đầu","Đang làm")) -> Chưa bắt đầu
A24: TỔNG | B24: 7 Sprint (7 Tuần) | C24: =SUM(C17:C23) -> 22 | D24: =SUM(D17:D23) -> 1 | E24: =SUM(E17:E23) -> 2 | F24: =TEXT(D24/C24,"0%")&" hoàn thành" -> 5% hoàn thành

Sheet PRD
A1: TÀI LIỆU YÊU CẦU SẢN PHẨM (PRD) — AI20K-075
A2: Mục lớn | B2: Hạng mục chi tiết | C2: Nội dung đặc tả yêu cầu sản phẩm | D2: Ghi chú
A3: 1. Tổng quan sản phẩm | B3: Mô tả | C3: Hệ thống VSF Student Risk Alert (VSF SRA) là giải pháp phân tích học thuật (Learning Analytics) sử dụng AI Agent để cảnh báo sớm các nguy cơ học tập và rèn luyện của học sinh K-12. Hệ thống giúp Ban Giám Hiệu và Giáo viên chủ động đưa ra các quyết định can thiệp sư phạm kịp thời dựa trên bằng chứng dữ liệu, thay thế cho quy trình báo cáo thủ công trễ hạn.
A4: 2. Đối tượng người dùng và Phân quyền (RBAC) | B4: Ban Giám Hiệu (Hiệu trưởng / Hiệu phó) | C4: - Xem dashboard vĩ mô toàn trường (read-only đối với dữ liệu điểm số). - Sử dụng trợ lý AI hỏi đáp tiếng Việt để tra cứu dữ liệu tổng hợp.
B5: Giáo viên chủ nhiệm & Giáo viên bộ môn | C5: - Quản lý, nhập/sửa điểm số học sinh thuộc lớp/môn phụ trách. - Tải lên đề thi và tài liệu môn học để chạy OCR và RAG phân tích. - Theo dõi danh sách học sinh có nguy cơ thuộc lớp chủ nhiệm hoặc bộ môn mình dạy để can thiệp kịp thời.
B6: Admin Hệ thống (System Admin) | C6: - Giám sát kỹ thuật và theo dõi các metrics vận hành của hệ thống (độ trễ phản hồi, độ chính xác của AI Agent, thống kê đánh giá/phản hồi chất lượng từ người dùng cuối) thông qua giao diện quản trị `/admin/ai-metrics`.
A7: 3. Yêu cầu Chức năng | B7: 3.1. Module Text-to-Query (Hỏi đáp ngôn ngữ tự nhiên) | C7: - Tiếp nhận câu hỏi ngôn ngữ tự nhiên tiếng Việt về kết quả học tập từ BGH và dịch thành câu lệnh truy vấn dữ liệu (SQL cho PostgreSQL hoặc Pandas Query). - Tích hợp lớp kiểm tra AST (`SQLGlot`) để chặn toàn bộ các lệnh thay đổi dữ liệu (`INSERT`, `UPDATE`, `DELETE`, `DROP`, `ALTER`). - Áp dụng Row-Level Security (RLS) bằng cách tự động chèn tham số `school_id` của người dùng vào câu truy vấn trước khi thực thi để cách ly dữ liệu.
B8: 3.2. Module Phân tích Yếu tố Tác động & Các Mô hình Học thuật | C8: - Yêu cầu tích hợp dữ liệu: - Hệ thống tự động thu thập và phân tích **6 nhóm yếu tố đầu vào** từ cơ sở dữ liệu làm biến số dự báo: 1. *Điểm số:* Lịch sử điểm số từ học bạ và sổ điểm (`fact_gradebooks`, `fact_subject_academic_records`). 2. *Mức độ hoàn thành bài tập / LMS:* Điểm số, tỷ lệ nộp bài tập tự học (`fact_so_assignment_grade`). 3. *Chuyên cần:* Số buổi vắng mặt có/không phép, đi muộn (`fact_absent_logs`, `fact_so_daily_attendance`). 4. *Hành vi rèn luyện:* Điểm cộng/trừ hành vi (`fact_behavior_logs`) hoặc các trường hợp chăm sóc đặc biệt (trầm cảm, bệnh lý mãn tính,…). 5. *Khảo sát học sinh:* Mức độ hài lòng của học sinh đối với môi trường học tập. 6. *Biến cố gia đình:* Thông tin biến cố gia đình tác động đến tâm lý học sinh. - Các mô hình toán / học máy bắt buộc: *Lưu ý quan trọng: Các mô hình toán và học máy dưới đây hiện chỉ mang tính chất **dự thảo đề xuất (proposed drafts)**, chưa được xác nhận chính thức sẽ sử dụng trong bài toán thực tế. Các tham số, trọng số hoặc mô hình có thể được thêm bớt hoặc thay đổi linh hoạt tùy thuộc vào mức độ đầy đủ của dữ liệu thu thập được để tránh phát sinh khối lượng công việc dư thừa. Các công thức toán học chi tiết hiện được ẩn đi bằng comment.* - **Mô hình dự báo nguy cơ học thuật sớm ($P(Fail)$):** Dự đoán xác suất học sinh trượt môn ($P(Fail) >= 0.7$) trước khi diễn ra các kỳ thi lớn (ví dụ: trước kỳ thi học kỳ) dựa trên dữ liệu điểm số thường xuyên, lịch sử học tập và chuyên cần để tự động gắn cờ cảnh báo (Đỏ/Vàng) giúp giáo viên kịp thời can thiệp. - **Phân cụm học sinh đa chiều bằng NMF (Non-negative Matrix Factorization):** Phân tích và phân rã ma trận đặc trưng hợp nhất bao gồm: **Ma trận điểm số + Ma trận hành vi rèn luyện + Ma trận tác động ngoại cảnh** của học sinh để nhóm học sinh thành 4 cụm mô thức học tập thực tế: Consistent Achievers (Ổn định), Procrastinators (Trì hoãn bứt phá), High-effort Low-performance (Chăm chỉ nhưng thi kém), High-risk Learners (Sa sút liên tục). - **Mô hình dự báo học lực cơ bản:** Dự báo xu hướng kết quả học tập thông qua Hồi quy tuyến tính hoặc LLM-based forecasting kết hợp các yếu tố hành vi/chuyên cần định tính để chỉ ra chiều hướng học tập đi lên hoặc đi xuống.
B9: 3.3. Module Multi-Agent System | C9: - Kiến trúc: Đồ thị trạng thái tuần hoàn (StateGraph) trên LangGraph được điều phối bởi **Supervisor Agent** (Tác tử giám sát): - *Data Agent:* Phục vụ truy xuất thông tin thô của học sinh, lớp học, điểm số. - *Stat Agent:* Thực hiện tính toán thống kê sâu. - *Report Agent:* Tự động sinh báo cáo hành chính (PDF/Word) kèm biểu đồ trực quan. - *Prediction Agent:* Thực thi mô hình dự báo học lực và xác định mức độ nguy cơ. - Phân quyền cho Data Agent: - Data Agent tuân thủ nghiêm ngặt cơ chế phân quyền RBAC của hệ thống (ADMIN/PRINCIPAL/GRADE_HEAD/HOMEROOM/SUBJECT_TEACHER/SUBJECT_HEAD). - Data Agent sử dụng Token xác thực của người dùng hiện tại để thực thi truy vấn, đảm bảo cách ly dữ liệu và không xảy ra đọc vượt quyền.
B10: 3.4. Module RAG + LLM & OCR | C10: - Pipeline RAG & OCR 1 (Ingestion): Quét giáo trình, sách giáo khoa, đề cương môn học dạng PDF/Ảnh -> OCR trích xuất văn bản -> Chunking & Embedding -> Lưu trữ vào **Qdrant Vector Database** phục vụ làm cơ sở tri thức đối chiếu. - Pipeline RAG & OCR 2 (Exam Analysis): Nhận file đề thi do giáo viên tải lên -> OCR trích xuất đề thi -> LLM đối chiếu với tri thức giáo trình trong Qdrant -> Đánh giá mức độ bám sát chương trình, phân loại Bloom các câu hỏi (Nhận biết, Thông hiểu, Vận dụng, Vận dụng cao) và xuất chỉ số độ khó đề thi (CDI - Content Difficulty Index).
A11: 4. Yêu cầu Phi chức năng | B11: 4.1. Bảo mật | C11: - Toàn bộ các API được bảo vệ bằng mã hóa JWT Token. - SQL Validator phải đảm bảo 100% không cho phép SQL Injection hoặc thực thi các lệnh thay đổi dữ liệu (`INSERT/UPDATE/DELETE`). - Dữ liệu giữa các trường học (school) phải được cách ly tuyệt đối ở tầng cơ sở dữ liệu và API truy vấn thông qua bộ lọc `school_id`.
B12: 4.2. Thiết kế Dữ liệu linh hoạt | C12: - ERD cơ sở dữ liệu phải cho phép lưu trữ và chuyển đổi linh hoạt giữa nhiều chuẩn điểm: hệ điểm 10, hệ điểm 6, hệ điểm chữ (A, B, C...), hoặc định tính Đạt/Chưa đạt để hệ thống chạy ổn định cho các chương trình đào tạo khác nhau.
B13: 4.3. Triển khai | C13: - Ứng dụng phải hỗ trợ đóng gói bằng Docker và triển khai dễ dàng lên các nền tảng đám mây (như Railway hoặc Render).
B14: 4.4. Giới hạn chi phí và tối ưu LLM | C14: - Áp dụng **cơ chế Cache Prompt** (lưu trữ tạm thời System Prompts, cấu trúc DB, và nội dung giáo trình mẫu) cho các API truy vấn LLM để tối ưu hóa chi phí token đầu vào (giảm 50-80% lượng token lặp lại) và tăng tốc phản hồi.

Sheet Mini-SRS
A1: Tài liệu Đặc tả Yêu cầu Rút gọn (MINI-SRS)
A2: Mục lớn | B2: Hạng mục chi tiết | C2: Nội dung đặc tả yêu cầu sản phẩm | D2: Ghi chú
A3: 1. Giới thiệu dự án | B3: Mô tả | C3: Hệ thống VSF Student Risk Alert (VSF SRA) là một giải pháp AI Agent kết hợp Phân tích học thuật (Learning Analytics) hỗ trợ Ban Giám Hiệu và Giáo viên các trường phổ thông (K-12) phát hiện sớm các nguy cơ học thuật/sư phạm của học sinh. Khác với các hệ thống quản lý điểm số tĩnh truyền thống, VSF SRA áp dụng các thuật toán phân tích học máy và thống kê nâng cao từ dữ liệu điểm số, chuyên cần và hành vi rèn luyện nhằm đưa ra cảnh báo kịp thời và đề xuất giải pháp phụ đạo sư phạm nhân văn, tích cực.
A4: 2. Đối tượng sử dụng (User Roles) | C4: Hệ thống xác định rõ 3 đối tượng người dùng chính tham gia vận hành và khai thác: - **Ban Giám Hiệu (PRINCIPAL):** - Xem các báo cáo trực quan và dashboard vĩ mô toàn trường (read-only đối với dữ liệu điểm số). - Tương tác với trợ lý AI bằng câu hỏi tiếng Việt để truy xuất dữ liệu tổng hợp. - **Giáo viên (CHỦ NHIỆM / BỘ MÔN):** - Xem danh sách cảnh báo học sinh có nguy cơ thuộc lớp chủ nhiệm hoặc các môn học mình giảng dạy. - Nhập, chỉnh sửa điểm số học sinh thuộc lớp/môn học được phân công. - Tải lên đề thi, giáo trình học tập của môn học để AI hỗ trợ phân tích ma trận kiến thức và độ khó. - **Admin Hệ thống (SYSTEM ADMIN):** - Giám sát kỹ thuật toàn bộ hệ thống. - Theo dõi metrics vận hành của hệ thống (đo lường độ trễ phản hồi, độ chính xác của AI Agent, thống kê đánh giá/phản hồi chất lượng từ người dùng cuối) thông qua giao diện quản trị `/admin/ai-metrics`.
A5: 3. Mô hình Dữ liệu linh hoạt (Flexible Grading Model) | C5: Để đảm bảo khả năng mở rộng cho nhiều trường học với các quy chế đánh giá khác nhau, hệ thống được thiết kế phi cứng nhắc (polymorphic): - **Hỗ trợ đa trường/cơ sở (Multi-school/Multi-campus):** Cách ly dữ liệu theo từng trường thông qua cơ chế chèn tự động điều kiện `school_id`. - **Hỗ trợ nhiều thang điểm và chuẩn đánh giá học thuật:** - *Thang điểm số:* Hệ 10 (Thông tư 22/2021/TT-BGDĐT kết hợp điểm số và nhận xét), Hệ 6 (quy chuẩn quốc tế), hoặc các hệ điểm số khác. - *Thang điểm chữ:* Hệ chữ A, B, C, D, F... dành cho các chương trình đào tạo quốc tế hoặc song ngữ. - *Đánh giá định tính:* Thang đánh giá Đạt (Pass) / Chưa đạt (Fail) dành cho các môn thể chất, nghệ thuật, trải nghiệm hướng nghiệp. - **Ánh xạ thang điểm quy chuẩn:** Cơ chế tự động chuẩn hóa các hệ điểm về phân phối chuẩn chuẩn hóa ($Z$-score) để phục vụ các thuật toán phân tích nâng cao một cách nhất quán.
A6: 4. Kiến trúc Hệ thống & Yêu cầu Chức năng (Functional Requirements) | B6: Module 1: Text-to-Query (Hỏi đáp dữ liệu học tập) | C6: - **Chức năng:** Cho phép Ban Giám Hiệu nhập câu hỏi bằng ngôn ngữ tự nhiên tiếng Việt (Ví dụ: *"Lớp 10A1 học kỳ 1 có bao nhiêu học sinh có nguy cơ trượt môn Toán?"*) và tự động dịch thành câu lệnh truy vấn dữ liệu (SQL cho PostgreSQL hoặc Pandas Query). - **Rào chắn an ninh (Guardrails):** - Sử dụng AST parser (`SQLGlot`) để quét và chặn toàn bộ các câu lệnh gây thay đổi dữ liệu (`INSERT`, `UPDATE`, `DELETE`, `DROP`, `ALTER`). - Chỉ cho phép các lệnh `SELECT` thuộc danh sách bảng được phân quyền (whitelist). - Tự động bắt buộc thêm điều kiện lọc `school_id` tương ứng với quyền truy cập của người dùng để tránh rò rỉ dữ liệu chéo giữa các trường học.
B7: Module 2: Multi-Agent System (Hệ thống đa tác tử) | C7: - **Kiến trúc:** Đồ thị trạng thái tuần hoàn (StateGraph) trên LangGraph dưới sự điều phối của một **Supervisor Agent** (Tác tử giám sát) phân phối nhiệm vụ cho các tác tử chuyên biệt: - *Data Agent:* Phụ trách tra cứu, kiểm toán và hiển thị dữ liệu học sinh, lớp học, điểm số thô. - *Stat Agent:* Tính toán các chỉ số thống kê toán học sư phạm nâng cao. - *Report Agent:* Tổng hợp kết quả, kết xuất các biểu đồ trực quan và sinh báo cáo tự động (PDF/Word). - *Prediction Agent:* Dự báo xu hướng học lực và đánh giá nguy cơ học thuật. - **Phân quyền dữ liệu cho Data Agent:** - Data Agent tuân thủ nghiêm ngặt cơ chế phân quyền RBAC của hệ thống (ADMIN/PRINCIPAL/GRADE_HEAD/HOMEROOM/SUBJECT_TEACHER/SUBJECT_HEAD). - Data Agent chỉ được phép truy vấn dữ liệu thông qua Token xác thực của người dùng hiện tại, tự động giới hạn phạm vi truy xuất (ví dụ: GV bộ môn chỉ được phép đọc điểm của học sinh thuộc các lớp mình trực tiếp giảng dạy).
B8: Module 3: RAG + LLM (Phân tích Đề thi và Giáo trình) | C8: - **Quy trình luồng xử lý RAG (RAG Ingestion & Query Flow):** 1. Ban Giám Hiệu hoặc Giáo viên tải lên các tài liệu nền tảng (sách giáo khoa, giáo trình môn học, đề cương ôn tập mẫu) dưới dạng file PDF hoặc hình ảnh. 2. Hệ thống kích hoạt module OCR để bóc tách văn bản thô, dọn dẹp dữ liệu nhiễu, chia nhỏ văn bản (chunking), tạo vector nhúng (embedding). 3. Các vector này được lưu trữ tập trung vào **Qdrant Vector Database**. 4. Khi giáo viên tải một đề thi mới lên để kiểm định, hệ thống thực thi OCR đề thi đó và truy vấn Vector DB Qdrant để so khớp, đối chiếu với tri thức giáo trình, xếp loại Bloom các câu hỏi và chấm chỉ số độ khó đề thi (CDI - Content Difficulty Index). - **Quy định Giới hạn Tài liệu Tải lên (Rate Limiting & File Constraints):** - Định dạng file được hỗ trợ: `.pdf`, `.png`, `.jpg`, `.jpeg`. - Giới hạn dung lượng: Tối đa 25MB đối với file PDF và tối đa 10MB đối với file hình ảnh.
B9: Module 4: OCR (Optical Character Recognition) | C9: - **Chức năng:** Trích xuất văn bản từ hình ảnh và PDF scan, được tích hợp trong hai pipeline: - *Pipeline Ingestion (Xử lý giáo trình):* Số hóa giáo trình học tập phục vụ nạp tri thức Vector DB phục vụ RAG. - *Pipeline Exam Analysis (Xử lý đề thi):* Số hóa đề kiểm tra do giáo viên tải lên để làm đầu vào so khớp và phân loại Bloom.
A10: 5. Các Thuật toán Phân tích Học thuật (Academic Algorithms) | C10: Hệ thống thu thập và phân tích **6 nhóm yếu tố đầu vào (Input Features)** từ cơ sở dữ liệu làm biến số dự báo: 1. **Điểm số:** Lịch sử điểm số từ học bạ và sổ điểm (`fact_gradebooks`, `fact_subject_academic_records`). 2. **Mức độ hoàn thành bài tập / LMS:** Tỷ lệ nộp bài và điểm số các bài tập tự học (`fact_so_assignment_grade`). 3. **Chuyên cần:** Tỷ lệ nghỉ học có phép/không phép, đi muộn học đường (`fact_absent_logs`, `fact_so_daily_attendance`). 4. **Hành vi rèn luyện:** Ghi nhận điểm rèn luyện, vi phạm kỷ luật hoặc hồ sơ chăm sóc đặc biệt (`fact_behavior_logs`). 5. **Khảo sát học sinh:** Mức độ hài lòng của học sinh đối với môi trường học tập. 6. **Biến cố gia đình:** Các thông tin đột xuất về hoàn cảnh gia đình tác động đến tâm lý học sinh. | D10: > [!NOTE] > **Lưu ý quan trọng:** Các mô hình toán và học máy dưới đây hiện chỉ mang tính chất **dự thảo đề xuất (proposed drafts)**, chưa được xác nhận chính thức sẽ sử dụng trong bài toán thực tế. Các tham số, trọng số hoặc mô hình có thể được thêm bớt hoặc thay đổi linh hoạt tùy thuộc vào mức độ đầy đủ của dữ liệu thu thập được để tránh phát sinh khối lượng công việc dư thừa. Các công thức toán học chi tiết hiện được ẩn đi để phục vụ việc thống nhất sau này.
B11: 5.1. Dự báo nguy cơ học thuật sớm ($P(Fail)$) | C11: Dự báo xác suất trượt môn hoặc sa sút học tập nghiêm trọng của học sinh trước khi diễn ra các kỳ thi lớn (ví dụ trước thi học kỳ) dựa trên dữ liệu điểm số thường xuyên, lịch sử học tập và chuyên cần nhằm giúp giáo viên kịp thời can thiệp sư phạm. Nếu xác suất dự báo vượt ngưỡng quy định ($\ge 0.7$), hệ thống sẽ tự động gắn cờ Đỏ (nguy cơ cao) trên Dashboard.
B12: 5.2. Phân cụm Học sinh đa chiều bằng NMF (Non-negative Matrix Factorization) | C12: Phân cụm đa chiều bằng cách phân tích và phân rã ma trận đặc trưng hợp nhất bao gồm: **Ma trận điểm số + Ma trận hành vi rèn luyện + Ma trận tác động ngoại cảnh** của học sinh. Thuật toán phân tách học sinh thành 4 cụm mô thức học tập thực tế: Consistent Achievers (Ổn định), Procrastinators (Trì hoãn bứt phá), High-effort Low-performance (Chăm chỉ nhưng thi kém), và High-risk Learners (Sa sút liên tục).
B13: 5.3. Mô hình dự báo học lực cơ bản (Trend/Regression hoặc LLM-based forecasting) | C13: - **Phương pháp thống kê/hồi quy (Trend/Regression):** Sử dụng hồi quy tuyến tính trên chuỗi điểm trung bình theo thời gian để tính toán hệ số góc (độ dốc) đo xu hướng tiến bộ (hệ số dương) hoặc sa sút học lực (hệ số âm). - **Phương pháp AI (LLM-based forecasting):** Sử dụng Large Language Model (LLM) để tổng hợp các đặc trưng định tính (hành vi rèn luyện, chuyên cần, biến cố gia đình) kết hợp với chuỗi điểm số lịch sử nhằm sinh ra các nhận định dự báo xu hướng học lực của học kỳ tiếp theo.
A14: 6. Yêu cầu Phi chức năng (Non-Functional Requirements) | C14: - **Bảo mật dữ liệu:** - Mã hóa 100% các API giao tiếp bằng JWT Token. - Phân tách và cách ly dữ liệu đa trường tuyệt đối ở tầng CSDL bằng tham số `school_id`. - **Giới hạn chi phí và tối ưu LLM:** - Áp dụng **cơ chế Cache Prompt** (lưu trữ tạm thời System Prompts, cấu trúc DB, và nội dung giáo trình mẫu) cho các API truy vấn LLM. Cơ chế này giúp tối ưu hóa chi phí token đầu vào (giảm tới 50-80% chi phí token lặp lại) và tăng tốc độ xử lý các câu hỏi liên tiếp của người dùng.

Sheet Project Charter
A1: PROJECT CHARTER — AI20K-075 | Nhóm 051
A2: Hệ Thống Cảnh Báo Sớm Học Sinh Có Nguy Cơ Sư Phạm (VSF Student Risk Alert - VSF SRA)
A4: 1. Thông tin dự án
A5: Tên dự án | B5: Hệ Thống Cảnh Báo Sớm Học Sinh Có Nguy Cơ Sư Phạm (VSF Student Risk Alert - VSF SRA)
A6: Người lập | B6: Thực tập sinh SRA
A7: Ngày lập | B7: 16/07/2026
A8: Phiên bản | B8: 1.0
A10: 2. Lý do thực hiện & Mục tiêu
A11: Vấn đề đang gặp | B11: Dữ liệu học tập (điểm số, chuyên cần, hành vi, LMS) của học sinh K-12 bị phân tán, rời rạc, gây khó khăn cho việc phát hiện sớm học sinh sa sút học lực hoặc gặp khó khăn học thuật/kỷ luật để can thiệp sư phạm kịp thời.
A12: Giải pháp đề xuất | B12: Xây dựng hệ thống cảnh báo sớm học sinh có nguy cơ dựa trên dữ liệu School Online Schema. Backend sử dụng mô hình Đa tác tử (Multi-Agent) trên LangGraph, Frontend hiển thị bản đồ nhiệt rủi ro học tập, phân cụm năng lực học tập đa chiều, chỉ báo P(Fail) trước thi, tích hợp OCR/RAG.
A13: Mục tiêu SMART (7 tuần) | B13: Trong 7 tuần (16/07 - 27/08/2026), hoàn thiện hệ thống VSF SRA tích hợp đầy đủ 4 module cốt lõi (Text-to-Query bảo mật bằng SQLGlot, Multi-Agent LangGraph phân tích sâu, RAG đối chiếu đề thi với Qdrant Vector DB, và OCR), độ chính xác Text-to-Query >= 85%, chạy online ổn định.
A15: 3. Phạm vi dự án
A16: # | B16: Trong phạm vi (In-scope) | F16: Ngoài phạm vi (Out-of-scope)
A17: # | B17: 1. Đồng bộ cấu trúc dữ liệu School Online Schema linh hoạt nhiều thang điểm. 2. Module Text-to-Query hỏi đáp tự nhiên tiếng Việt cho BGH bảo mật qua SQLGlot. 3. Module Multi-Agent System điều phối các tác tử (Data, Stat, Report, Prediction). 4. Mô hình dự báo nguy cơ học thuật sớm trước thi P(Fail), phân cụm học sinh đa chiều NMF (Grades + Behavior + External factors), và hồi quy xu hướng học lực. 5. Module RAG + LLM so khớp đề thi với giáo trình trong Qdrant Vector DB. 6. OCR số hóa giáo trình (Ingestion pipeline) và bóc tách đề thi (Exam Analysis pipeline). 7. Bảo mật RBAC 3 vai trò (BGH, Giáo viên, Admin Hệ thống) và Cache Prompt tối ưu chi phí LLM. | F17: 1. BGH sửa đổi trực tiếp điểm số (BGH chỉ có quyền read-only). 2. Chatbot trả lời tự do ngoài phạm vi nghiệp vụ sư phạm/học vụ. 3. Tự động đánh giá nhân cách/nhãn mác tiêu cực cho học sinh. 4. Tự động gửi cảnh báo rủi ro học thuật ra bên ngoài mà không qua sự phê duyệt của GV (Human-in-the-loop).
A19: 4. Đối tác liên quan (Stakeholders)
A20: Vai trò | B20: Họ tên / Đơn vị | D20: Mức ảnh hưởng | F20: Trách nhiệm
A21: Sponsor / Đối tác | B21: Quỹ VSF (Vietnam Sustainability Forum) | D21: Cao | F21: Đặt bài toán, cung cấp bối cảnh nghiệp vụ, định hướng bài toán, đánh giá sản phẩm qua các buổi Demo định kỳ.
A22: Khách hàng / Người dùng | B22: Ban Giám Hiệu & Giáo viên các trường K-12 | D22: Cao | F22: Cung cấp yêu cầu nghiệp vụ thực tế, tham gia kiểm thử UAT và đưa ra phản hồi cải tiến.
A23: Thực tập sinh SRA | B23: Thực tập sinh | D23: Cao | F23: Thiết kế kiến trúc, phát triển backend, frontend, tích hợp các mô hình AI và thực hiện kiểm thử.
A24: Mentor | B24: Nguyễn Thịnh | D24: Cao | F24: Hướng dẫn chuyên môn, đánh giá tài liệu mini-SRS, review code và kiến trúc hệ thống.
A26: 5. Cột mốc chính (Milestones)
A27: Mã | B27: Mốc quan trọng | C27: Mô tả chi tiết | D27: Từ ngày | E27: Đến ngày | F27: Người chịu trách nhiệm | G27: Trạng thái | H27: Kết quả giao nộp
A28: M1 | B28: Hoàn thành Onboarding & Kế hoạch | C28: Chốt mục tiêu, phạm vi dự án, mini-SRS & kế hoạch sprint 7 tuần | D28: 16/07/2026 | E28: 18/07/2026 | F28: Thực tập sinh | G28: Hoàn thành | H28: mini-SRS, prd, sprint plan
A29: M2 | B29: Setup môi trường & ERD | C29: Setup repo, docker dev env, thiết kế ERD, DB PostgreSQL và dữ liệu giả lập | D29: 20/07/2026 | E29: 24/07/2026 | F29: Thực tập sinh | G29: Chưa bắt đầu | H29: Sơ đồ ERD, seed script dữ liệu mock, Dockerfile/compose
A30: M3 | B30: Demo 1 — Text-to-Query | C30: Xây dựng pipeline NL-to-SQL tiếng Việt, tích hợp SQLGlot bảo mật, REST API | D30: 27/07/2026 | E30: 31/07/2026 | F30: Thực tập sinh | G30: Chưa bắt đầu | H30: REST API Text-to-Query, API docs, unit tests
A31: M4 | B31: Nghiên cứu mô hình dự báo | C31: Liệt kê các yếu tố tác động, lập trình tính toán chỉ số, tích hợp cờ cảnh báo sớm | D31: 03/08/2026 | E31: 07/08/2026 | F31: Thực tập sinh | G31: Chưa bắt đầu | H31: Báo cáo phân tích yếu tố tác động, tài liệu đề xuất tham số
A32: M5 | B32: Demo 2 — Multi-Agent | C32: Phát triển multi-agent LangGraph (Supervisor, Data, Stat, Report, Prediction) | D32: 10/08/2026 | E32: 14/08/2026 | F32: Thực tập sinh | G32: Chưa bắt đầu | H32: Multi-agent pipeline demo, Report generator hoạt động
A33: M6 | B33: Demo 3 — RAG & OCR | C33: Pipeline RAG lưu Vector DB Qdrant, OCR bóc tách đề thi/giáo trình, so khớp đề thi | D33: 17/08/2026 | E33: 21/08/2026 | F33: Thực tập sinh | G33: Chưa bắt đầu | H33: RAG & OCR pipeline demo, Qdrant setup script, API phân tích đề thi
A34: M7 | B34: Sản phẩm hoàn chỉnh & Bàn giao | C34: UAT toàn diện, sửa lỗi, Dashboard cho BGH/GV, tài liệu hướng dẫn kỹ thuật, demo cuối kỳ | D34: 24/08/2026 | E34: 27/08/2026 | F34: Thực tập sinh | G34: Chưa bắt đầu | H34: Toàn bộ source code, Dashboard UI/UX chạy thật, tài liệu HDSD, biên bản bàn giao
A35: 6. Nguồn lực & Ngân sách
A36: Nhân sự | B36: 2 người × ~40 giờ/tuần = ~80 giờ/tuần (cả hai vai trò Fullstack)
A37: Công cụ (miễn phí) | B37: GitHub + GitHub Actions (CI), Neon (PostgreSQL), Railway (deploy), Vercel, Discord, Google Drive, OpenAI gpt-4o-mini, LangGraph/LangChain
A38: Công cụ (cần duyệt chi phí) | B38: Chi phí gọi LLM API (gpt-4o-mini) — hiện trong hạn mức miễn phí/thấp
A39: Tổng ngân sách dự kiến | B39: ≈ 0đ (sử dụng gói miễn phí/giáo dục cho hạ tầng & API)
A41: 7. Rủi ro chính & Cách xử lý
A42: # | B42: Rủi ro | C42: Xác suất | D42: Tác động | E42: Cách phòng tránh / Xử lý
A43: 1 | B43: Text-to-SQL sinh SQL sai / LLM ảo tưởng số liệu | C43: Trung bình | D43: Cao | E43: Guardrail SQLGlot: chỉ SELECT, whitelist 21 bảng, chèn school_id; LLM chỉ tổng hợp số liệu thô từ DB, không tự tính.
A44: 2 | B44: Rò rỉ dữ liệu chéo giữa các trường (multi-tenant) | C44: Trung bình | D44: Cao | E44: Cô lập theo school_id qua ContextVar; RLS theo role; luôn set/reset context ở /chat.
A45: 3 | B45: RAG (Vector Store) chưa kịp triển khai trong MVP | C45: Cao | D45: Trung bình | E45: Đã có config chroma_persist_dir; coi RAG là tính năng mở rộng sau MVP, không chặn luồng chính.
A46: 4 | B46: Frontend nối API thật trễ (đang dùng mock) | C46: Cao | D46: Cao | E46: Ưu tiên Sprint 5: login lưu JWT, trang /scores & dashboard nối API; xử lý 401/403 theo role.
...

Sheet Backlog
A1: BACKLOG — DANH SÁCH CÔNG VIỆC THEO SPRINT
A2: Mã việc | B2: Tên công việc | C2: Mã US | D2: Mô tả chi tiết | E2: Người phụ trách | F2: Hạn chót | G2: Trạng thái | H2: Ghi chú
A3: Sprint 1 — Tuần 0: Khởi động, thống nhất phạm vi, mini-SRS & thiết kế kiến trúc
A4: T-001 | B4: Đánh giá kiến trúc hệ thống cũ | C4: US-007 | D4: Đánh giá dự án VinUni cũ để tái sử dụng Auth/RBAC phù hợp | E4: Thực tập sinh SRA | F4: 17/07/2026 | G4: Hoàn thành | H4: Tái sử dụng JWT/Auth
A5: T-002 | B5: Thiết kế sơ đồ kiến trúc hệ thống mới | C5: US-007 | D5: Vẽ sơ đồ kiến trúc 4 module: Text-to-Query, Multi-Agent, RAG, OCR | E5: Thực tập sinh SRA | F5: 18/07/2026 | G5: Đang làm | H5: Sơ đồ kiến trúc mới
A6: T-003 | B6: Viết tài liệu đặc tả mini-SRS & PRD | C6: US-007 | D6: Hoàn thiện tài liệu mini-SRS, PRD và kế hoạch sprint chi tiết | E6: Thực tập sinh SRA | F6: 18/07/2026 | G6: Đang làm | H6: Mentor đã duyệt
A7: Sprint 2 — Tuần 1: Thiết lập môi trường & ERD dữ liệu giả
A8: T-004 | B8: Thiết kế ERD & Schema cơ sở dữ liệu | C8: US-001 | D8: Thiết kế ERD hỗ trợ linh hoạt thang điểm (Grading Scale Polymorphism) | E8: Thực tập sinh SRA | F8: 22/07/2026 | G8: Chưa bắt đầu | H8: Hỗ trợ hệ 10, chữ, đạt/chưa đạt
A9: T-005 | B9: Setup repo, Docker dev env & CI/CD | C9: US-007 | D9: Thiết lập GitHub repository, CI cơ bản và môi trường ảo phát triển | E9: Thực tập sinh SRA | F9: 23/07/2026 | G9: Chưa bắt đầu | H9: Python 3.11+, Docker
A10: T-006 | B10: Setup database PostgreSQL & Dữ liệu giả lập | C10: US-001 | D10: Tạo DB và seed script sinh dữ liệu giả lập (synthetic) cho THCS | E10: Thực tập sinh SRA | F10: 24/07/2026 | G10: Chưa bắt đầu | H10: Hỗ trợ chạy thử Text-to-Query
A11: T-007 | B11: Thiết lập LLM provider & Multi-Agent framework | C11: US-007 | D11: Chọn LLM provider (gpt-4o-mini) và setup LangGraph | E11: Thực tập sinh SRA | F11: 24/07/2026 | G11: Chưa bắt đầu | H11: Thiết lập config credentials
A12: Sprint 3 — Tuần 2: Module Text-to-Query (NL-to-Query)
A13: T-008 | B13: Phát triển pipeline NL-to-SQL bằng LLM | C13: US-001 | D13: Xây dựng pipeline dịch câu hỏi tiếng Việt thành SQL query | E13: Thực tập sinh SRA | F13: 28/07/2026 | G13: Chưa bắt đầu | H13: Sử dụng LangChain/LangGraph
A14: T-009 | B14: Tích hợp bộ kiểm tra bảo mật SQLGlot | C14: US-001 | D14: AST parser chặn INSERT/UPDATE/DELETE và chèn school_id tự động | E14: Thực tập sinh SRA | F14: 29/07/2026 | G14: Chưa bắt đầu | H14: Lớp bảo mật an toàn DB
A15: T-010 | B15: Xây dựng API endpoints & bộ test-case câu hỏi mẫu | C15: US-001 | D15: REST API /chat cho Text-to-Query và bộ câu hỏi mẫu kiểm thử | E15: Thực tập sinh SRA | F15: 31/07/2026 | G15: Chưa bắt đầu | H15: API Documentation, độ chính xác >=85%
A16: Sprint 4 — Tuần 3: Phân tích các yếu tố tác động
A17: T-011 | B17: Nghiên cứu & Phân tích các yếu tố tác động | C17: US-002 | D17: Xác định mức độ ảnh hưởng của 6 nhóm yếu tố đầu vào đến học lực | E17: Thực tập sinh SRA | F17: 04/08/2026 | G17: Chưa bắt đầu | H17: Điểm, LMS, chuyên cần, hành vi...
A18: T-012 | B18: Lập trình thuật toán tính chỉ số & dự báo trước kỳ thi | C18: US-002 | D18: Cài đặt logic dự báo xác suất trượt môn P(Fail) trước kỳ thi lớn | E18: Thực tập sinh SRA | F18: 06/08/2026 | G18: Chưa bắt đầu | H18: Dự báo sớm để can thiệp
A19: T-013 | B19: Thiết kế cơ chế gắn cờ cảnh báo sớm vào DB | C19: US-002 | D19: Tự động cập nhật cờ rủi ro (Đỏ/Vàng/Xanh) cho học sinh | E19: Thực tập sinh SRA | F19: 07/08/2026 | G19: Chưa bắt đầu | H19: Lưu trữ kết quả phân tích trong DB
A20: Sprint 5 — Tuần 4: Module Multi-Agent & Dự báo học lực
A21: T-014 | B21: Thiết kế & Phát triển multi-agent LangGraph | C21: US-003 | D21: Xây dựng Supervisor Agent và 4 sub-agents (Data, Stat, Report, Prediction) | E21: Thực tập sinh SRA | F21: 11/08/2026 | G21: Chưa bắt đầu | H21: LangGraph StateGraph
A22: T-015 | B22: Lập trình các thuật toán phân tích chuyên sâu | C22: US-003 | D22: Triển khai phân cụm NMF đa chiều và hồi quy xu hướng học lực | E22: Thực tập sinh SRA | F22: 12/08/2026 | G22: Chưa bắt đầu | H22: Phân cụm 3 ma trận kết hợp
A23: T-016 | B23: Phát triển Report Generator tự động sinh báo cáo | C23: US-003 | D23: Tự động sinh báo cáo sư phạm markdown và xuất định dạng PDF/Word | E23: Thực tập sinh SRA | F23: 13/08/2026 | G23: Chưa bắt đầu | H23: Báo cáo chi tiết cho BGH/GV
A24: Sprint 6 — Tuần 5: Module RAG + LLM & OCR
A25: T-017 | B25: Thiết lập Qdrant Vector DB & Pipeline RAG | C25: US-005 | D25: Chunking, embedding giáo trình môn học và nạp tri thức vào Qdrant | E25: Thực tập sinh SRA | F25: 18/08/2026 | G25: Chưa bắt đầu | H25: Rate Limiting & File Constraints (max 25MB)
A26: T-018 | B26: Phát triển logic đối chiếu đề thi và xếp loại Bloom | C26: US-004 | D26: Kết hợp RAG + LLM đánh giá đề thi và xuất chỉ số độ khó (CDI) | E26: Thực tập sinh SRA | F26: 20/08/2026 | G26: Chưa bắt đầu | H26: So khớp kiến thức đề thi & giáo trình
A27: T-019 | B27: Triển khai module OCR bóc tách đề thi & giáo trình | C27: US-006 | D27: OCR số hóa tài liệu giáo trình và đề kiểm tra tải lên | E27: Thực tập sinh SRA | F27: 21/08/2026 | G27: Chưa bắt đầu | H27: Hỗ trợ ảnh/PDF scan (max 10MB/25MB)
A28: Sprint 7 — Tuần 6: Kiểm thử toàn diện, UI Dashboard, Triển khai & Bàn giao
A29: T-020 | B29: Kiểm thử UAT toàn diện & Sửa lỗi | C29: US-007 | D29: Chạy kiểm thử tích hợp, unit tests, UAT với dữ liệu giả lập | E29: Thực tập sinh SRA | F29: 25/08/2026 | G29: Chưa bắt đầu | H29: Đối tác nghiệm thu sản phẩm
A30: T-021 | B30: Tối ưu hóa chi phí LLM bằng Cache Prompt | C30: US-007 | D30: Tích hợp cơ chế cache prompt cho các API RAG và Text-to-Query | E30: Thực tập sinh SRA | F30: 26/08/2026 | G30: Chưa bắt đầu | H30: Giảm chi phí token đầu vào
A31: T-022 | B31: Triển khai ứng dụng (Railway/Docker) & Bàn giao | C31: US-007 | D31: Đóng gói Docker, triển khai live, bàn giao source code & tài liệu | E31: Thực tập sinh SRA | F31: 27/08/2026 | G31: Chưa bắt đầu | H31: Demo cuối kỳ thành công

Sheet Bug
A1: THEO DÕI LỖI (BUG TRACKING)
A2: Báo cáo ngay khi phát hiện lỗi — Cập nhật trạng thái khi xử lý xong
A3: STT | B3: Mã lỗi | C3: Tiêu đề lỗi | D3: Mô tả chi tiết | E3: Cách tái hiện | F3: Ưu tiên | G3: Mã US | H3: Người xử lý | I3: Trạng thái | J3: Ngày sửa / Ghi chú
A4: 1 | B4: BUG-001 | C4: [Ví dụ: Chatbot không trả lời khi câu hỏi có dấu tiếng Việt] | D4: [Mô tả chi tiết hiện tượng] | E4: 1. Mở /chat 2. Nhập câu hỏi có dấu 3. Quan sát phản hồi | F4: Trung bình | G4: US-008 | H4: [Họ tên] | I4: Đang sửa
A5: 2 | B5: BUG-002
A6: 3 | B6: BUG-003
A7: 4 | B7: BUG-004
A8: 5 | B8: BUG-005
A9: 6 | B9: BUG-006
A10: 7 | B10: BUG-007
A11: 8 | B11: BUG-008
A12: 9 | B12: BUG-009
A13: 10 | B13: BUG-010
A14: 11 | B14: BUG-011
A15: 12 | B15: BUG-012
A16: 13 | B16: BUG-013
... A23: 20 | B23: BUG-020
A25: THANG MỨC NGHIÊM TRỌNG
A26: Nghiêm trọng | B26: Ứng dụng sập hoặc mất dữ liệu — Không thể sử dụng được
A27: Cao | B27: Tính năng chính không hoạt động đúng, ảnh hưởng nhiều người dùng
A28: Trung bình | B28: Tính năng phụ bị lỗi, trải nghiệm không tốt nhưng vẫn dùng được
A29: Thấp | B29: Lỗi nhỏ, liên quan giao diện, không ảnh hưởng chức năng

Sheet Đường link
A1: TẬP HỢP ĐƯỜNG LINK QUAN TRỌNG
A2: Lưu mọi đường link liên quan đến dự án — Cập nhật ngay khi có link mới
A3: STT | B3: Phân loại | C3: Nội dung / Mô tả | D3: Địa chỉ (URL) | E3: Người quản lý | F3: Ghi chú
A4: Mã nguồn và Triển khai
A5: 1 | C5: Kho lưu mã nguồn (GitHub Repository) | D5: https://github.com/AI20K-Build-Cohort-2/C2-App-051 | E5: Cả nhóm
A6: 2 | C6: Địa chỉ sản phẩm (Production) | D6: https://c2-app-051.up.railway.app/ | E6: Điệp | F6: Railway
A7: 3 | C7: API Docs (FastAPI) | D7: https://c2-app-051.up.railway.app/docs | E7: Cả nhóm | F7: Auto-docs
A8: 4 | C8: Quy trình tự động (CI/CD) | D8: GitHub Actions (.github/workflows/ci.yml) | E8: Điệp | F8: ruff + pytest
A9: Tài liệu thiết kế
A10: 5 | C10: PRD & Kế hoạch triển khai | D10: docs/gate_1/ (PRD.md, KE_HOACH_TRIEN_KHAI…) | E10: Cả nhóm
A11: 6 | C11: Sơ đồ kiến trúc hệ thống | D11: docs/architecture_diagram.md, docs/gate_2/architecture.md | E11: Cả nhóm
A12: 7 | C12: Sơ đồ cơ sở dữ liệu (ERD) | D12: docs/schema.sql | E12: Khánh | F12: 21 bảng
A13: 8 | C13: UI mockup (vnEdu style) | D13: docs/gate_1/ui_gate_1.png | E13: Điệp | F13: Figma/PNG
A14: Liên lạc và Hợp tác
A15: 9 | C15: Kênh Discord nhóm | D15: [Dán link] | E15: Cả nhóm
A16: 10 | C16: Ổ đĩa dùng chung (Google Drive) | D16: Thư mục AI20K | E16: Khánh

Sheet User Story
A1: DANH SÁCH USER STORY — AI20K-075
A2: Mã | B2: Tên câu chuyện | C2: Mô tả ngắn | D2: Vai trò | E2: Tôi muốn | F2: Để đạt được | G2: Ưu tiên | H2: Trạng thái
A3: US-001 | B3: Hỏi đáp học vụ tự nhiên | C3: Hỏi đáp bằng tiếng Việt | D3: Ban Giám Hiệu | E3: Hỏi đáp bằng câu hỏi tiếng Việt tự nhiên về kết quả học tập của trường | F3: Nhận được thông tin số liệu và báo cáo truy vấn chính xác dưới sự bảo vệ của SQLGlot | G3: Bắt buộc | H3: Đang làm
A4: US-002 | B4: Nhận diện học sinh nguy cơ | C4: Cảnh báo học sinh nguy cơ sớm | D4: Giáo viên | E4: Xem danh sách học sinh có nguy cơ cao (P(Fail) >= 0.7) của lớp/môn mình dạy trước kỳ thi lớn | F4: Kịp thời đưa ra can thiệp sư phạm để hỗ trợ học sinh | G4: Bắt buộc | H4: Chưa bắt đầu
A5: US-003 | B5: Phân cụm học sinh đa chiều | C5: Phân cụm học sinh NMF | D5: Ban Giám Hiệu | E5: Xem phân loại học sinh thành 4 cụm mô thức dựa trên tổ hợp Điểm số + Hành vi + Tác động ngoại cảnh | F5: Đưa ra các phương án giáo dục và phụ đạo cá nhân hóa một cách nhân văn | G5: Nên có | H5: Chưa bắt đầu
A6: US-004 | B6: So khớp đề kiểm tra với giáo trình | C6: RAG đánh giá đề kiểm tra | D6: Giáo viên | E6: Tải lên đề kiểm tra và đối chiếu với giáo trình chuẩn được lưu trữ trong Qdrant Vector DB | F6: Đánh giá mức độ bám sát kiến thức, phân loại Bloom và tính chỉ số độ khó đề thi (CDI) | G6: Nên có | H6: Chưa bắt đầu
A7: US-005 | B7: Số hóa giáo trình học tập | C7: OCR nạp dữ liệu giáo trình | D7: Ban Giám Hiệu | E7: Tải lên tài liệu giáo trình/đề cương mẫu (PDF/Ảnh, tối đa 25MB/10MB) để hệ thống tự động OCR và lưu vào Qdrant Vector DB | F7: Xây dựng kho tri thức nền tảng cho việc so khớp đề thi | G7: Nên có | H7: Chưa bắt đầu
A8: US-006 | B8: Bóc tách đề thi tự động | C8: OCR phân tích đề thi | D8: Giáo viên | E8: Tải lên file ảnh chụp/scan đề thi (PDF/Ảnh) để hệ thống tự động bóc tách | F8: Thực hiện phân tích RAG nhanh chóng không cần nhập tay | G8: Có thì tốt | H8: Chưa bắt đầu
A9: US-007 | B9: Giám sát chất lượng & metrics | C9: Dashboard giám sát kỹ thuật | D9: Admin Hệ thống | E9: Xem thống kê các chỉ số vận hành (độ trễ phản hồi, độ chính xác AI, đánh giá chất lượng từ BGH/GV) | F9: Đảm bảo hệ thống hoạt động ổn định và tối ưu chi phí (Cache Prompt) | G9: Bắt buộc | H9: Chưa bắt đầu
A11: THANG MỨC ƯU TIÊN
A12: Bắt buộc | B12: Sản phẩm không hoạt động nếu thiếu — Phải hoàn thành
A13: Nên có | B13: Tăng giá trị đáng kể nhưng không ảnh hưởng hoạt động cốt lõi
A14: Có thì tốt | B14: Làm nếu còn thời gian — Không ảnh hưởng nếu bỏ qua
A15: Không làm | B15: Ngoài phạm vi giai đoạn này
